Workbook

Sheet Task 5
C1: TASK 5: CAMPAIGN EFFECTIVENESS
M2: Campaign status | N2: During | R2: Campaign status | S2: During
A3: 5.1.1) Total and average impressions, likes, clicks per campaign | I3: 5.1.2) Engagement uplift during vs before campaign | M3: 5.2.1) Campaign with highest ROI | R3: 5.2.2) Campaign with strongest follower growth
A4: Campaigns | B4: Total Impressions | C4: Average Impressions | D4: Total Likes | E4: Average Likes | F4: Total Clicks | G4: Average Clicks | I4: Campaign | J4: Average of Engagement Rate | K4: Engagement Uplift (%) | M4: Campaign | N4: Average Engagement_Rate | O4: Average Ad_Spend | P4: ROI | R4: Campaign | S4: Sum of Net follower growth
A5: ChillVibes | B5: 6331868 | C5: 41116.026 | D5: 471034 | E5: 3058.6623 | F5: 28708 | G5: 186.41558 | I5: ChillVibes | K5: =((GETPIVOTDATA("Engagement Rate",$I$4,"Campaign_Name","ChillVibes","Campaign status","During")-GETPIVOTDATA("Engagement Rate",$I$4,"Campaign_Name","ChillVibes","Campaign status","Before")) / GETPIVOTDATA("Engagement Rate",$I$4,"Campaign_Name","ChillVibes","Campaign status","Before")) * 100 -> 28.705719 | M5: ChillVibes | N5: 6.2493333 | O5: 13430.667 | P5: =( GETPIVOTDATA("Average Engagement_Rate",$M$4,"Campaign name","ChillVibes") / GETPIVOTDATA("Average Ad_Spend",$M$4,"Campaign name","ChillVibes") ) * 100 -> 0.046530329 | R5: SummerBeats | S5: 13558
A6: IndieWave | B6: 4039305 | C6: 42971.33 | D6: 274455 | E6: 2919.734 | F6: 18717 | G6: 199.11702 | I6: Before | J6: 0.093905542 | M6: IndieWaves | N6: 6.9173333 | O6: 16422 | P6: =(GETPIVOTDATA("Average Engagement_Rate",$M$4,"Campaign name","IndieWaves") / GETPIVOTDATA("Average Ad_Spend",$M$4,"Campaign name","IndieWaves")) * 100 -> 0.042122356 | R6: IndieWaves | S6: 12726
A7: SummerBeats | B7: 1233853 | C7: 42546.655 | D7: 89871 | E7: 3099 | F7: 5557 | G7: 191.62069 | I7: During | J7: 0.1208618 | M7: SummerBeats | N7: 7.1393333 | O7: 16849.4 | P7: =( GETPIVOTDATA("Average Engagement_Rate",$M$4,"Campaign name","SummerBeats") / GETPIVOTDATA("Average Ad_Spend",$M$4,"Campaign name","SummerBeats")) * 100 -> 0.04237144 | R7: Wrapped2024 | S7: 11361
A8: Wrapped2024 | B8: 865406 | C8: 37626.348 | D8: 61815 | E8: 2687.6087 | F8: 4614 | G8: 200.6087 | I8: IndieWave | K8: =((GETPIVOTDATA("Engagement Rate",$I$4,"Campaign_Name","IndieWave","Campaign status","During")-GETPIVOTDATA("Engagement Rate",$I$4,"Campaign_Name","IndieWave","Campaign status","Before")) / GETPIVOTDATA("Engagement Rate",$I$4,"Campaign_Name","IndieWave","Campaign status","Before")) * 100 -> 28.290476 | M8: Wrapped2024 | N8: 6.1106667 | O8: 16255.133 | P8: =(GETPIVOTDATA("Average Engagement_Rate",$M$4,"Campaign name","Wrapped2024") / GETPIVOTDATA("Average Ad_Spend",$M$4,"Campaign name","Wrapped2024")) * 100 -> 0.037592227 | R8: ChillVibes | S8: 10142
A9: Grand Total | B9: 12470432 | C9: 41568.107 | D9: 897175 | E9: 2990.5833 | F9: 57596 | G9: 191.98667 | I9: Before | J9: 0.086490218 | R9: Grand Total | S9: 47787
I10: During | J10: 0.11095871
I11: SummerBeats | K11: =((GETPIVOTDATA("Engagement Rate",$I$4,"Campaign_Name","SummerBeats","Campaign status","During")-GETPIVOTDATA("Engagement Rate",$I$4,"Campaign_Name","SummerBeats","Campaign status","Before")) / GETPIVOTDATA("Engagement Rate",$I$4,"Campaign_Name","SummerBeats","Campaign status","Before")) * 100 -> -13.6172
I12: Before | J12: 0.090961113
I13: During | J13: 0.078574757
I14: Wrapped2024 | K14: =((GETPIVOTDATA("Engagement Rate",$I$4,"Campaign_Name","Wrapped2024","Campaign Status","During")-GETPIVOTDATA("Engagement Rate",$I$4,"Campaign_Name","Wrapped2024","Campaign Status","Before")) / GETPIVOTDATA("Engagement Rate",$I$4,"Campaign_Name","Wrapped2024","Campaign Status","Before") ) * 100 -> 0.10990207
I15: Before | J15: 0.095499997
I16: During | J16: 0.095604953

Sheet Post (5.1)
A1: Post ID | B1: Platform | C1: Date | D1: Content Type | E1: Post Text | F1: Likes | G1: Shares | H1: Comments | I1: Impressions | J1: Reach | K1: Clicks | L1: Hashtags Used | M1: Campaign_Name | N1: Engagement Rate | O1: Campaign start date | P1: Campaign end date | Q1: Campaign status
A2: SP001 | B2: Instagram | C2: 45781 | D2: Text | E2: Discover fresh beats on Spotify! | F2: 2414 | G2: 245 | H2: 137 | I2: 21181 | J2: 45292 | K2: 133 | L2: #SoundtrackOfLife,#NowPlaying | M2: ChillVibes | N2: =( Posts__2[[#This Row],[Likes]]+Posts__2[[#This Row],[Comments]]+Posts__2[[#This Row],[Shares]] ) / Posts__2[[#This Row],[Impressions]] -> 0.1320051 | O2: =_xlfn.XLOOKUP(Posts__2[[#This Row],[Campaign_Name]],'Campaign Metadata'!A:A,'Campaign Metadata'!B:B) -> 45667 | P2: =_xlfn.XLOOKUP(Posts__2[[#This Row],[Campaign_Name]],'Campaign Metadata'!A:A,'Campaign Metadata'!C:C) -> 45698 | Q2: =IF(AND(Posts__2[[#This Row],[Date]]>=Posts__2[[#This Row],[Campaign start date]],Posts__2[[#This Row],[Date]]<=Posts__2[[#This Row],[Campaign end date]]),"During","Before") -> Before
A3: SP002 | B3: Instagram | C3: 45689 | D3: Text | E3: Explore the latest podcasts now. | F3: 1934 | G3: 210 | H3: 393 | I3: 29129 | J3: 73287 | K3: 273 | L3: #DiscoverWeekly | M3: IndieWave | N3: =( Posts__2[[#This Row],[Likes]]+Posts__2[[#This Row],[Comments]]+Posts__2[[#This Row],[Shares]] ) / Posts__2[[#This Row],[Impressions]] -> 0.087095335 | O3: =_xlfn.XLOOKUP(Posts__2[[#This Row],[Campaign_Name]],'Campaign Metadata'!A:A,'Campaign Metadata'!B:B) -> 45717 | P3: =_xlfn.XLOOKUP(Posts__2[[#This Row],[Campaign_Name]],'Campaign Metadata'!A:A,'Campaign Metadata'!C:C) -> 45747 | Q3: =IF(AND(Posts__2[[#This Row],[Date]]>=Posts__2[[#This Row],[Campaign start date]],Posts__2[[#This Row],[Date]]<=Posts__2[[#This Row],[Campaign end date]]),"During","Before") -> Before
A4: SP003 | B4: Twitter | C4: 45629 | D4: Story | E4: New music just dropped. Hit play! | F4: 3092 | G4: 177 | H4: 81 | I4: 47533 | J4: 29220 | K4: 121 | L4: #MusicForEveryone,#NowPlaying | M4: ChillVibes | N4: =( Posts__2[[#This Row],[Likes]]+Posts__2[[#This Row],[Comments]]+Posts__2[[#This Row],[Shares]] ) / Posts__2[[#This Row],[Impressions]] -> 0.070477353 | O4: =_xlfn.XLOOKUP(Posts__2[[#This Row],[Campaign_Name]],'Campaign Metadata'!A:A,'Campaign Metadata'!B:B) -> 45667 | P4: =_xlfn.XLOOKUP(Posts__2[[#This Row],[Campaign_Name]],'Campaign Metadata'!A:A,'Campaign Metadata'!C:C) -> 45698 | Q4: =IF(AND(Posts__2[[#This Row],[Date]]>=Posts__2[[#This Row],[Campaign start date]],Posts__2[[#This Row],[Date]]<=Posts__2[[#This Row],[Campaign end date]]),"During","Before") -> Before
A5: SP004 | B5: Instagram | C5: 45629 | D5: Text | E5: Wrapped is here! Relive your top tracks 🎧 | F5: 3173 | G5: 229 | H5: 197 | I5: 29604 | J5: 21809 | K5: 272 | L5: #SoundtrackOfLife,#NowPlaying | M5: ChillVibes | N5: =( Posts__2[[#This Row],[Likes]]+Posts__2[[#This Row],[Comments]]+Posts__2[[#This Row],[Shares]] ) / Posts__2[[#This Row],[Impressions]] -> 0.12157141 | O5: =_xlfn.XLOOKUP(Posts__2[[#This Row],[Campaign_Name]],'Campaign Metadata'!A:A,'Campaign Metadata'!B:B) -> 45667 | P5: =_xlfn.XLOOKUP(Posts__2[[#This Row],[Campaign_Name]],'Campaign Metadata'!A:A,'Campaign Metadata'!C:C) -> 45698 | Q5: =IF(AND(Posts__2[[#This Row],[Date]]>=Posts__2[[#This Row],[Campaign start date]],Posts__2[[#This Row],[Date]]<=Posts__2[[#This Row],[Campaign end date]]),"During","Before") -> Before
A6: SP005 | B6: YouTube | C6: 45388 | D6: Text | E6: Music that moves you-only on Spotify. | F6: 2748 | G6: 145 | H6: 315 | I6: 24401 | J6: 61182 | K6: 200 | L6: #DiscoverWeekly,#SpotifyWrapped | M6: IndieWave | N6: =( Posts__2[[#This Row],[Likes]]+Posts__2[[#This Row],[Comments]]+Posts__2[[#This Row],[Shares]] ) / Posts__2[[#This Row],[Impressions]] -> 0.13147002 | O6: =_xlfn.XLOOKUP(Posts__2[[#This Row],[Campaign_Name]],'Campaign Metadata'!A:A,'Campaign Metadata'!B:B) -> 45717 | P6: =_xlfn.XLOOKUP(Posts__2[[#This Row],[Campaign_Name]],'Campaign Metadata'!A:A,'Campaign Metadata'!C:C) -> 45747 | Q6: =IF(AND(Posts__2[[#This Row],[Date]]>=Posts__2[[#This Row],[Campaign start date]],Posts__2[[#This Row],[Date]]<=Posts__2[[#This Row],[Campaign end date]]),"During","Before") -> Before
A7: SP006 | B7: YouTube | C7: 45456 | D7: Text | E7: What's your vibe today? #SpotifyHits | F7: 3882 | G7: 239 | H7: 275 | I7: 58748 | J7: 44646 | K7: 149 | L7: #DiscoverWeekly,#SpotifyWrapped | M7: IndieWave | N7: =( Posts__2[[#This Row],[Likes]]+Posts__2[[#This Row],[Comments]]+Posts__2[[#This Row],[Shares]] ) / Posts__2[[#This Row],[Impressions]] -> 0.074828079 | O7: =_xlfn.XLOOKUP(Posts__2[[#This Row],[Campaign_Name]],'Campaign Metadata'!A:A,'Campaign Metadata'!B:B) -> 45717 | P7: =_xlfn.XLOOKUP(Posts__2[[#This Row],[Campaign_Name]],'Campaign Metadata'!A:A,'Campaign Metadata'!C:C) -> 45747 | Q7: =IF(AND(Posts__2[[#This Row],[Date]]>=Posts__2[[#This Row],[Campaign start date]],Posts__2[[#This Row],[Date]]<=Posts__2[[#This Row],[Campaign end date]]),"During","Before") -> Before
A8: SP007 | B8: Twitter | C8: 45645 | D8: Story | E8: Get into the groove with our new drop! | F8: 4674 | G8: 409 | H8: 327 | I8: 20756 | J8: 63599 | K8: 212 | L8: #SoundtrackOfLife,#NowPlaying | M8: ChillVibes | N8: =( Posts__2[[#This Row],[Likes]]+Posts__2[[#This Row],[Comments]]+Posts__2[[#This Row],[Shares]] ) / Posts__2[[#This Row],[Impressions]] -> 0.26064752 | O8: =_xlfn.XLOOKUP(Posts__2[[#This Row],[Campaign_Name]],'Campaign Metadata'!A:A,'Campaign Metadata'!B:B) -> 45667 | P8: =_xlfn.XLOOKUP(Posts__2[[#This Row],[Campaign_Name]],'Campaign Metadata'!A:A,'Campaign Metadata'!C:C) -> 45698 | Q8: =IF(AND(Posts__2[[#This Row],[Date]]>=Posts__2[[#This Row],[Campaign start date]],Posts__2[[#This Row],[Date]]<=Posts__2[[#This Row],[Campaign end date]]),"During","Before") -> Before
A9: SP008 | B9: Twitter | C9: 45421 | D9: Story | E9: Wrapped is here! Relive your top tracks 🎧 | F9: 1428 | G9: 347 | H9: 67 | I9: 21148 | J9: 19712 | K9: 120 | L9: #DiscoverWeekly,#MusicForEveryone | M9: ChillVibes | N9: =( Posts__2[[#This Row],[Likes]]+Posts__2[[#This Row],[Comments]]+Posts__2[[#This Row],[Shares]] ) / Posts__2[[#This Row],[Impressions]] -> 0.087100435 | O9: =_xlfn.XLOOKUP(Posts__2[[#This Row],[Campaign_Name]],'Campaign Metadata'!A:A,'Campaign Metadata'!B:B) -> 45667 | P9: =_xlfn.XLOOKUP(Posts__2[[#This Row],[Campaign_Name]],'Campaign Metadata'!A:A,'Campaign Metadata'!C:C) -> 45698 | Q9: =IF(AND(Posts__2[[#This Row],[Date]]>=Posts__2[[#This Row],[Campaign start date]],Posts__2[[#This Row],[Date]]<=Posts__2[[#This Row],[Campaign end date]]),"During","Before") -> Before
A10: SP009 | B10: Twitter | C10: 45823 | D10: Text | E10: Top trending tracks updated daily! | F10: 4432 | G10: 223 | H10: 299 | I10: 59016 | J10: 21742 | K10: 171 | L10: #NowPlaying | M10: ChillVibes | N10: =( Posts__2[[#This Row],[Likes]]+Posts__2[[#This Row],[Comments]]+Posts__2[[#This Row],[Shares]] ) / Posts__2[[#This Row],[Impressions]] -> 0.083943337 | O10: =_xlfn.XLOOKUP(Posts__2[[#This Row],[Campaign_Name]],'Campaign Metadata'!A:A,'Campaign Metadata'!B:B) -> 45667 | P10: =_xlfn.XLOOKUP(Posts__2[[#This Row],[Campaign_Name]],'Campaign Metadata'!A:A,'Campaign Metadata'!C:C) -> 45698 | Q10: =IF(AND(Posts__2[[#This Row],[Date]]>=Posts__2[[#This Row],[Campaign start date]],Posts__2[[#This Row],[Date]]<=Posts__2[[#This Row],[Campaign end date]]),"During","Before") -> Before
A11: SP010 | B11: Twitter | C11: 45630 | D11: Text | E11: Wrapped is here! Relive your top tracks 🎧 | F11: 2357 | G11: 274 | H11: 172 | I11: 21566 | J11: 66829 | K11: 284 | L11: #NowPlaying | M11: ChillVibes | N11: =( Posts__2[[#This Row],[Likes]]+Posts__2[[#This Row],[Comments]]+Posts__2[[#This Row],[Shares]] ) / Posts__2[[#This Row],[Impressions]] -> 0.12997311 | O11: =_xlfn.XLOOKUP(Posts__2[[#This Row],[Campaign_Name]],'Campaign Metadata'!A:A,'Campaign Metadata'!B:B) -> 45667 | P11: =_xlfn.XLOOKUP(Posts__2[[#This Row],[Campaign_Name]],'Campaign Metadata'!A:A,'Campaign Metadata'!C:C) -> 45698 | Q11: =IF(AND(Posts__2[[#This Row],[Date]]>=Posts__2[[#This Row],[Campaign start date]],Posts__2[[#This Row],[Date]]<=Posts__2[[#This Row],[Campaign end date]]),"During","Before") -> Before
A12: SP011 | B12: Twitter | C12: 45357 | D12: Text | E12: Discover fresh beats on Spotify! | F12: 1971 | G12: 370 | H12: 306 | I12: 31316 | J12: 27897 | K12: 88 | L12: #SoundtrackOfLife | M12: IndieWave | N12: =( Posts__2[[#This Row],[Likes]]+Posts__2[[#This Row],[Comments]]+Posts__2[[#This Row],[Shares]] ) / Posts__2[[#This Row],[Impressions]] -> 0.084525482 | O12: =_xlfn.XLOOKUP(Posts__2[[#This Row],[Campaign_Name]],'Campaign Metadata'!A:A,'Campaign Metadata'!B:B) -> 45717 | P12: =_xlfn.XLOOKUP(Posts__2[[#This Row],[Campaign_Name]],'Campaign Metadata'!A:A,'Campaign Metadata'!C:C) -> 45747 | Q12: =IF(AND(Posts__2[[#This Row],[Date]]>=Posts__2[[#This Row],[Campaign start date]],Posts__2[[#This Row],[Date]]<=Posts__2[[#This Row],[Campaign end date]]),"During","Before") -> Before
A13: SP012 | B13: Instagram | C13: 45426 | D13: Text | E13: Discover fresh beats on Spotify! | F13: 1485 | G13: 353 | H13: 244 | I13: 38419 | J13: 38556 | K13: 86 | L13: #SoundtrackOfLife,#NowPlaying | M13: ChillVibes | N13: =( Posts__2[[#This Row],[Likes]]+Posts__2[[#This Row],[Comments]]+Posts__2[[#This Row],[Shares]] ) / Posts__2[[#This Row],[Impressions]] -> 0.054191936 | O13: =_xlfn.XLOOKUP(Posts__2[[#This Row],[Campaign_Name]],'Campaign Metadata'!A:A,'Campaign Metadata'!B:B) -> 45667 | P13: =_xlfn.XLOOKUP(Posts__2[[#This Row],[Campaign_Name]],'Campaign Metadata'!A:A,'Campaign Metadata'!C:C) -> 45698 | Q13: =IF(AND(Posts__2[[#This Row],[Date]]>=Posts__2[[#This Row],[Campaign start date]],Posts__2[[#This Row],[Date]]<=Posts__2[[#This Row],[Campaign end date]]),"During","Before") -> Before
... A301: SP300 | B301: Instagram | C301: 45329 | D301: Text | E301: Music that moves you-only on Spotify. | F301: 1883 | G301: 432 | H301: 397 | I301: 28759 | J301: 18691 | K301: 270 | L301: #SoundtrackOfLife,#NowPlaying | M301: ChillVibes | N301: =( Posts__2[[#This Row],[Likes]]+Posts__2[[#This Row],[Comments]]+Posts__2[[#This Row],[Shares]] ) / Posts__2[[#This Row],[Impressions]] -> 0.094300914 | O301: =_xlfn.XLOOKUP(Posts__2[[#This Row],[Campaign_Name]],'Campaign Metadata'!A:A,'Campaign Metadata'!B:B) -> 45667 | P301: =_xlfn.XLOOKUP(Posts__2[[#This Row],[Campaign_Name]],'Campaign Metadata'!A:A,'Campaign Metadata'!C:C) -> 45698 | Q301: =IF(AND(Posts__2[[#This Row],[Date]]>=Posts__2[[#This Row],[Campaign start date]],Posts__2[[#This Row],[Date]]<=Posts__2[[#This Row],[Campaign end date]]),"During","Before") -> Before

Sheet Campaign Metadata
A1: Campaign_Name | B1: Start_Date | C1: End_Date | D1: Objective | E1: Total_Budget | F1: Target_Platforms | G1: Primary_Hashtags
A2: SummerBeats | B2: 45458 | C2: 45488 | D2: Brand Awareness | E2: 175000 | F2: Instagram,YouTube | G2: #SpotifyWrapped,#MusicForEveryone
A3: Wrapped2024 | B3: 45627 | C3: 45657 | D3: Engagement | E3: 225000 | F3: Twitter,YouTube | G3: #SpotifyWrapped,#NowPlaying
A4: ChillVibes | B4: 45667 | C4: 45698 | D4: Product Launch | E4: 200000 | F4: Instagram,Twitter | G4: #ChillVibes,#SoundtrackOfLife
A5: IndieWave | B5: 45717 | C5: 45747 | D5: Traffic | E5: 160000 | F5: Facebook,Instagram | G5: #DiscoverWeekly,#IndieWave

Sheet Engagement Summary
A1: Week_Start_Date | B1: Platform | C1: New_Followers | D1: Unfollows | E1: Total_Followers | F1: Engagement_Rate | G1: Ad_Spend | H1: Net follower growth | I1: Campaign name | J1: Campaign status
A2: 45446 | B2: Instagram | C2: 1402 | D2: 68 | E2: 124562 | F2: 9.92 | G2: 23125 | H2: =Engagement_Summary68[[#This Row],[New_Followers]]-Engagement_Summary68[[#This Row],[Unfollows]] -> 1334
A3: 45446 | B3: Twitter | C3: 995 | D3: 86 | E3: 227958 | F3: 8.05 | G3: 22788 | H3: =Engagement_Summary68[[#This Row],[New_Followers]]-Engagement_Summary68[[#This Row],[Unfollows]] -> 909
A4: 45446 | B4: YouTube | C4: 1472 | D4: 296 | E4: 370242 | F4: 7.72 | G4: 7810 | H4: =Engagement_Summary68[[#This Row],[New_Followers]]-Engagement_Summary68[[#This Row],[Unfollows]] -> 1176
A5: 45453 | B5: Instagram | C5: 1018 | D5: 90 | E5: 92474 | F5: 9.4 | G5: 11966 | H5: =Engagement_Summary68[[#This Row],[New_Followers]]-Engagement_Summary68[[#This Row],[Unfollows]] -> 928
A6: 45453 | B6: Twitter | C6: 1461 | D6: 64 | E6: 328902 | F6: 9.02 | G6: 26298 | H6: =Engagement_Summary68[[#This Row],[New_Followers]]-Engagement_Summary68[[#This Row],[Unfollows]] -> 1397
A7: 45453 | B7: YouTube | C7: 545 | D7: 93 | E7: 391621 | F7: 9.96 | G7: 22029 | H7: =Engagement_Summary68[[#This Row],[New_Followers]]-Engagement_Summary68[[#This Row],[Unfollows]] -> 452
A8: 45460 | B8: Instagram | C8: 881 | D8: 291 | E8: 95885 | F8: 5.29 | G8: 12391 | H8: =Engagement_Summary68[[#This Row],[New_Followers]]-Engagement_Summary68[[#This Row],[Unfollows]] -> 590 | I8: SummerBeats | J8: During
A9: 45460 | B9: Twitter | C9: 1414 | D9: 131 | E9: 245947 | F9: 8.3 | G9: 14477 | H9: =Engagement_Summary68[[#This Row],[New_Followers]]-Engagement_Summary68[[#This Row],[Unfollows]] -> 1283 | I9: SummerBeats | J9: During
A10: 45460 | B10: YouTube | C10: 1472 | D10: 170 | E10: 250428 | F10: 4.66 | G10: 25040 | H10: =Engagement_Summary68[[#This Row],[New_Followers]]-Engagement_Summary68[[#This Row],[Unfollows]] -> 1302 | I10: SummerBeats | J10: During
A11: 45467 | B11: Instagram | C11: 809 | D11: 197 | E11: 87186 | F11: 9.48 | G11: 22619 | H11: =Engagement_Summary68[[#This Row],[New_Followers]]-Engagement_Summary68[[#This Row],[Unfollows]] -> 612 | I11: SummerBeats | J11: During
A12: 45467 | B12: Twitter | C12: 1371 | D12: 250 | E12: 128620 | F12: 7.11 | G12: 12399 | H12: =Engagement_Summary68[[#This Row],[New_Followers]]-Engagement_Summary68[[#This Row],[Unfollows]] -> 1121 | I12: SummerBeats | J12: During
A13: 45467 | B13: YouTube | C13: 844 | D13: 144 | E13: 126015 | F13: 9.65 | G13: 22456 | H13: =Engagement_Summary68[[#This Row],[New_Followers]]-Engagement_Summary68[[#This Row],[Unfollows]] -> 700 | I13: SummerBeats | J13: During
A14: 45474 | B14: Instagram | C14: 786 | D14: 72 | E14: 178615 | F14: 5.43 | G14: 19328 | H14: =Engagement_Summary68[[#This Row],[New_Followers]]-Engagement_Summary68[[#This Row],[Unfollows]] -> 714 | I14: SummerBeats | J14: During
A15: 45474 | B15: Twitter | C15: 845 | D15: 250 | E15: 218228 | F15: 4.52 | G15: 21107 | H15: =Engagement_Summary68[[#This Row],[New_Followers]]-Engagement_Summary68[[#This Row],[Unfollows]] -> 595 | I15: SummerBeats | J15: During
A16: 45474 | B16: YouTube | C16: 1218 | D16: 101 | E16: 300397 | F16: 4.33 | G16: 12277 | H16: =Engagement_Summary68[[#This Row],[New_Followers]]-Engagement_Summary68[[#This Row],[Unfollows]] -> 1117 | I16: SummerBeats | J16: During
A17: 45481 | B17: Instagram | C17: 797 | D17: 130 | E17: 340121 | F17: 8.52 | G17: 11684 | H17: =Engagement_Summary68[[#This Row],[New_Followers]]-Engagement_Summary68[[#This Row],[Unfollows]] -> 667 | I17: SummerBeats | J17: During
A18: 45481 | B18: Twitter | C18: 1471 | D18: 100 | E18: 76866 | F18: 8.55 | G18: 14412 | H18: =Engagement_Summary68[[#This Row],[New_Followers]]-Engagement_Summary68[[#This Row],[Unfollows]] -> 1371 | I18: SummerBeats | J18: During
A19: 45481 | B19: YouTube | C19: 1253 | D19: 136 | E19: 193131 | F19: 7.99 | G19: 15924 | H19: =Engagement_Summary68[[#This Row],[New_Followers]]-Engagement_Summary68[[#This Row],[Unfollows]] -> 1117 | I19: SummerBeats | J19: During
... A22: 45488 | B22: YouTube | C22: 981 | D22: 69 | E22: 206921 | F22: 8.42 | G22: 10495 | H22: =Engagement_Summary68[[#This Row],[New_Followers]]-Engagement_Summary68[[#This Row],[Unfollows]] -> 912 | I22: SummerBeats | J22: During
A23: 45495 | B23: Instagram | C23: 866 | D23: 74 | E23: 204121 | F23: 9.34 | G23: 7797 | H23: =Engagement_Summary68[[#This Row],[New_Followers]]-Engagement_Summary68[[#This Row],[Unfollows]] -> 792
A24: 45495 | B24: Twitter | C24: 547 | D24: 183 | E24: 266350 | F24: 5.65 | G24: 15595 | H24: =Engagement_Summary68[[#This Row],[New_Followers]]-Engagement_Summary68[[#This Row],[Unfollows]] -> 364
A25: 45495 | B25: YouTube | C25: 1241 | D25: 116 | E25: 380606 | F25: 4.2 | G25: 24617 | H25: =Engagement_Summary68[[#This Row],[New_Followers]]-Engagement_Summary68[[#This Row],[Unfollows]] -> 1125
A26: 45502 | B26: Instagram | C26: 973 | D26: 104 | E26: 376358 | F26: 3.87 | G26: 9847 | H26: =Engagement_Summary68[[#This Row],[New_Followers]]-Engagement_Summary68[[#This Row],[Unfollows]] -> 869
A27: 45502 | B27: Twitter | C27: 611 | D27: 197 | E27: 79423 | F27: 5.82 | G27: 13644 | H27: =Engagement_Summary68[[#This Row],[New_Followers]]-Engagement_Summary68[[#This Row],[Unfollows]] -> 414
A28: 45502 | B28: YouTube | C28: 983 | D28: 134 | E28: 352178 | F28: 3.55 | G28: 11421 | H28: =Engagement_Summary68[[#This Row],[New_Followers]]-Engagement_Summary68[[#This Row],[Unfollows]] -> 849
A29: 45509 | B29: Instagram | C29: 1449 | D29: 96 | E29: 200636 | F29: 9.92 | G29: 15613 | H29: =Engagement_Summary68[[#This Row],[New_Followers]]-Engagement_Summary68[[#This Row],[Unfollows]] -> 1353
A30: 45509 | B30: Twitter | C30: 752 | D30: 170 | E30: 132756 | F30: 8.17 | G30: 23900 | H30: =Engagement_Summary68[[#This Row],[New_Followers]]-Engagement_Summary68[[#This Row],[Unfollows]] -> 582
A31: 45509 | B31: YouTube | C31: 937 | D31: 179 | E31: 318098 | F31: 5.3 | G31: 5836 | H31: =Engagement_Summary68[[#This Row],[New_Followers]]-Engagement_Summary68[[#This Row],[Unfollows]] -> 758
A32: 45516 | B32: Instagram | C32: 1060 | D32: 83 | E32: 68724 | F32: 5.98 | G32: 5624 | H32: =Engagement_Summary68[[#This Row],[New_Followers]]-Engagement_Summary68[[#This Row],[Unfollows]] -> 977
A33: 45516 | B33: Twitter | C33: 1456 | D33: 265 | E33: 115505 | F33: 7.49 | G33: 10311 | H33: =Engagement_Summary68[[#This Row],[New_Followers]]-Engagement_Summary68[[#This Row],[Unfollows]] -> 1191
A34: 45516 | B34: YouTube | C34: 1109 | D34: 205 | E34: 276722 | F34: 9.38 | G34: 8274 | H34: =Engagement_Summary68[[#This Row],[New_Followers]]-Engagement_Summary68[[#This Row],[Unfollows]] -> 904
... A79: 45621 | B79: YouTube | C79: 1313 | D79: 159 | E79: 197183 | F79: 9.71 | G79: 6625 | H79: =Engagement_Summary68[[#This Row],[New_Followers]]-Engagement_Summary68[[#This Row],[Unfollows]] -> 1154
A80: 45628 | B80: Instagram | C80: 895 | D80: 87 | E80: 171271 | F80: 6.68 | G80: 23329 | H80: =Engagement_Summary68[[#This Row],[New_Followers]]-Engagement_Summary68[[#This Row],[Unfollows]] -> 808 | I80: Wrapped2024 | J80: During
A81: 45628 | B81: Twitter | C81: 1027 | D81: 156 | E81: 111293 | F81: 5.51 | G81: 7299 | H81: =Engagement_Summary68[[#This Row],[New_Followers]]-Engagement_Summary68[[#This Row],[Unfollows]] -> 871 | I81: Wrapped2024 | J81: During
A82: 45628 | B82: YouTube | C82: 990 | D82: 286 | E82: 351493 | F82: 7.97 | G82: 14496 | H82: =Engagement_Summary68[[#This Row],[New_Followers]]-Engagement_Summary68[[#This Row],[Unfollows]] -> 704 | I82: Wrapped2024 | J82: During
A83: 45635 | B83: Instagram | C83: 875 | D83: 264 | E83: 345631 | F83: 9.18 | G83: 25703 | H83: =Engagement_Summary68[[#This Row],[New_Followers]]-Engagement_Summary68[[#This Row],[Unfollows]] -> 611 | I83: Wrapped2024 | J83: During
A84: 45635 | B84: Twitter | C84: 599 | D84: 194 | E84: 105622 | F84: 6.44 | G84: 15108 | H84: =Engagement_Summary68[[#This Row],[New_Followers]]-Engagement_Summary68[[#This Row],[Unfollows]] -> 405 | I84: Wrapped2024 | J84: During
A85: 45635 | B85: YouTube | C85: 630 | D85: 248 | E85: 119054 | F85: 5.02 | G85: 18867 | H85: =Engagement_Summary68[[#This Row],[New_Followers]]-Engagement_Summary68[[#This Row],[Unfollows]] -> 382 | I85: Wrapped2024 | J85: During
A86: 45642 | B86: Instagram | C86: 1350 | D86: 233 | E86: 171670 | F86: 4.53 | G86: 17574 | H86: =Engagement_Summary68[[#This Row],[New_Followers]]-Engagement_Summary68[[#This Row],[Unfollows]] -> 1117 | I86: Wrapped2024 | J86: During
...
